<!--
Meta Description: # C++における「catch」: 例外処理の基本 ## 概要 C++の「catch」は、例外処理のメカニズムの一部であり、tryブロック内で発生した例外を捕捉するために使用されます。この機能により、プログラムの異常終了を防ぎ、エラー処理を行うことができます。 ## ドキュメンテーション ### 目...
Meta Keywords: catch, std, try, cpp, const
-->

# C++における「catch」: 例外処理の基本

## 概要
C++の「catch」は、例外処理のメカニズムの一部であり、tryブロック内で発生した例外を捕捉するために使用されます。この機能により、プログラムの異常終了を防ぎ、エラー処理を行うことができます。

## ドキュメンテーション
### 目的
「catch」は、tryブロックで発生した例外を捕捉し、適切なエラーハンドリングを行うために使用されます。これにより、プログラムの安定性が向上し、ユーザーに対してより良い体験を提供できます。

### 使用法
基本的な構文は以下の通りです：

```cpp
try {
    // 例外が発生する可能性のあるコード
} catch (const ExceptionType& e) {
    // 例外を処理するコード
}
```

- **try**ブロック内に、例外が発生する可能性のあるコードを記述します。
- **catch**ブロックは、指定した型の例外が発生したときに実行されるコードを含みます。

### 詳細
- **複数のcatch**: 同じtryブロックに対して複数のcatchブロックを持つことができ、異なる型の例外に対して異なる処理を行うことができます。
  
```cpp
try {
    // 何らかの処理
} catch (const std::runtime_error& e) {
    // runtime_errorに対する処理
} catch (const std::exception& e) {
    // その他の例外に対する処理
}
```

- **catch(...)**: すべての例外を捕捉することができるcatchブロックも使用することができます。この場合、具体的な例外の型を指定することなく、すべての例外を処理します。

```cpp
try {
    // 何らかの処理
} catch (...) {
    // すべての例外に対する処理
}
```

## 例
以下は、基本的な使用例です。

```cpp
#include <iostream>
#include <stdexcept>

int main() {
    try {
        throw std::runtime_error("エラーが発生しました");
    } catch (const std::runtime_error& e) {
        std::cout << "例外を捕捉しました: " << e.what() << std::endl;
    }
    return 0;
}
```

この例では、`std::runtime_error`型の例外を投げ、catchブロックでそれを捕捉しています。

## 説明
- **誤解を招く点**: 例外を捕捉する際には、catchブロックの順序が重要です。特定の例外を最初に捕捉し、一般的な例外を後にするようにすることが推奨されます。これは、特定の例外が一般的な例外に捕捉されてしまうのを防ぐためです。

- **例外の再スロー**: catchブロック内で例外を処理した後、再度例外をスローすることも可能です。この場合、`throw;`のみを使用します。

```cpp
try {
    // 何らかの処理
} catch (const std::exception& e) {
    // エラーログを出力
    std::cerr << "エラー: " << e.what() << std::endl;
    throw; // 再スロー
}
```

## 1行の要約
C++の「catch」は、例外を捕捉し、適切なエラーハンドリングを行うための重要な機能です。