<!--
Meta Description: # C++中的throw关键字详解 ## 摘要 在C++编程中，`throw`关键字用于抛出异常，以便在程序运行时处理错误情况。它是异常处理机制的核心部分，使得程序能够优雅地处理意外情况。 ## 文档 ### 目的 `throw`关键字的主要目的是用于引发异常。当程序运行过程中遇到错误或不可预见的情...
Meta Keywords: throw, std, catch, const, cpp
-->

# C++中的throw关键字详解

## 摘要
在C++编程中，`throw`关键字用于抛出异常，以便在程序运行时处理错误情况。它是异常处理机制的核心部分，使得程序能够优雅地处理意外情况。

## 文档
### 目的
`throw`关键字的主要目的是用于引发异常。当程序运行过程中遇到错误或不可预见的情况时，可以使用`throw`来引发一个异常对象，从而将控制权转移到最近的异常处理程序。

### 使用方法
在C++中，`throw`后面可以跟一个表达式，这个表达式的值将被视为异常对象。异常对象通常是一个类的实例，能够提供错误信息或其他上下文信息。

```cpp
throw expression;
```

### 详细说明
- 当使用`throw`抛出异常时，程序将查找与该异常匹配的`catch`块。如果找到匹配的`catch`块，程序将跳入该块执行相应的处理逻辑。
- 如果没有找到匹配的`catch`块，程序将终止并输出错误信息。
- 可以抛出任何类型的对象，包括基本数据类型、类对象、指针等，但通常建议抛出继承自`std::exception`的对象，以便提供一致的错误处理。

## 示例
以下是使用`throw`的基本示例：

### 示例1：抛出基本数据类型
```cpp
#include <iostream>

void checkAge(int age) {
    if (age < 18) {
        throw "年龄小于18岁";
    }
    std::cout << "年龄合法" << std::endl;
}

int main() {
    try {
        checkAge(15);
    } catch (const char* msg) {
        std::cerr << "异常: " << msg << std::endl;
    }
    return 0;
}
```

### 示例2：抛出自定义异常
```cpp
#include <iostream>
#include <stdexcept>

class MyException : public std::exception {
public:
    const char* what() const noexcept override {
        return "自定义异常被抛出";
    }
};

void testFunction() {
    throw MyException();
}

int main() {
    try {
        testFunction();
    } catch (const std::exception& e) {
        std::cerr << "异常: " << e.what() << std::endl;
    }
    return 0;
}
```

## 说明
- **常见陷阱**：在使用`throw`时，确保异常类型的匹配，避免使用不相关的类型。
- **资源管理**：使用`throw`时，需注意资源管理，尤其是在堆上分配的资源。可以使用智能指针或RAII（资源获取即初始化）模式来管理资源，以避免内存泄漏。
- **异常安全**：在设计函数时，需考虑异常安全性，确保在异常发生时程序状态保持一致。

## 一句话总结
`throw`关键字在C++中用于引发异常，帮助程序优雅地处理错误情况。