<!--
Meta Description: # C++におけるtry文の使い方と詳細ガイド ## 概要 C++における`try`文は、例外処理メカニズムの一部であり、プログラムの実行中に発生する可能性のあるエラーや例外を捕捉して処理するために使用されます。これにより、プログラムの安定性を向上させ、エラーが発生した場合の適切な対処が可能になりま...
Meta Keywords: try, catch, std, runtime_error, における
-->

# C++におけるtry文の使い方と詳細ガイド

## 概要
C++における`try`文は、例外処理メカニズムの一部であり、プログラムの実行中に発生する可能性のあるエラーや例外を捕捉して処理するために使用されます。これにより、プログラムの安定性を向上させ、エラーが発生した場合の適切な対処が可能になります。

## ドキュメント
### 目的
`try`文は、特定のコードブロック内で発生する可能性のある例外を監視し、その例外を適切に処理するための構文です。C++では、`try`ブロック内で発生した例外は、`catch`ブロックで捕捉され、エラーハンドリングを実行します。

### 使用方法
`try`文は以下の構文で使用します：

```cpp
try {
    // 例外が発生する可能性のあるコード
} catch (const 型名& e) {
    // 例外を処理するコード
}
```

- `try`ブロック内には、例外が発生する可能性のあるコードを記述します。
- `catch`ブロックは、その例外をキャッチして処理するためのコードを記述します。

### 詳細
- `try`ブロック内で発生した例外は、対応する`catch`ブロックに制御が移ります。
- `catch`ブロックは、捕捉する例外の型に応じて複数記述することができます。
- 例外が発生しなかった場合、`catch`ブロックは実行されません。

## 例
以下は、`try`文を用いた基本的な例です。

```cpp
#include <iostream>
#include <stdexcept>

int main() {
    try {
        throw std::runtime_error("エラーが発生しました。");
    } catch (const std::runtime_error& e) {
        std::cout << "捕捉された例外: " << e.what() << std::endl;
    }
    return 0;
}
```

この例では、`runtime_error`型の例外が発生し、それを捕捉してエラーメッセージを出力します。

## 説明
### 一般的な落とし穴
- **例外の再スロー**: `catch`ブロック内で例外を再スローすることができますが、その際には適切な注意が必要です。再スローする場合は、`throw;`を使用します。
- **例外未捕捉**: `try`ブロック内で発生した例外がどの`catch`ブロックにもマッチしない場合、プログラムは異常終了します。すべての例外を捕捉するには、一般的な`catch(...)`を使用することが推奨されます。

### 追加の注意点
- C++の例外処理は、パフォーマンスに影響を与える可能性があるため、頻繁に発生するエラー処理に使用するのは避けるべきです。
- `try`/`catch`は、リソース管理やクリーンアップに対して有効ですが、リソースの解放は、RAII（Resource Acquisition Is Initialization）パターンを使用することが推奨されます。

## 一文要約
C++における`try`文は、例外処理を行うための構文であり、エラー発生時の安定したプログラム実行を支援します。