<!--
Meta Description: # Understanding the "try" Keyword in C++ ## Synopsis The `try` keyword in C++ is part of the exception handling mechanism that allows developers to wr...
Meta Keywords: exception, catch, std, try, block
-->

# Understanding the "try" Keyword in C++

## Synopsis
The `try` keyword in C++ is part of the exception handling mechanism that allows developers to write robust code by managing runtime errors effectively. It facilitates the definition of a block of code to monitor for exceptions, enabling more graceful error handling.

## Documentation
The `try` block is used in conjunction with `catch` and `throw` to create a structured approach to error handling in C++. The primary purpose of the `try` block is to enclose a section of code that may potentially throw exceptions. If an exception occurs, control is transferred to the corresponding `catch` block, where the exception can be handled appropriately.

### Purpose
- To define a block of code that may produce exceptions.
- To enable developers to manage errors systematically without crashing the program.
  
### Usage
A `try` block is typically followed by one or more `catch` blocks that handle specific types of exceptions. The syntax is as follows:

```cpp
try {
    // Code that may throw an exception
} catch (const ExceptionType& e) {
    // Code to handle the exception
}
```

### Details
- You can have multiple `catch` blocks for different exception types following a single `try` block.
- If an exception is thrown, the program will search for the first matching `catch` block, and the code in that block will be executed.
- If no matching `catch` block is found, the program will terminate.
- It is recommended to catch exceptions by reference to avoid slicing and unnecessary copies.

## Examples
### Basic Example 1: Handling Division by Zero

```cpp
#include <iostream>
#include <stdexcept>

int divide(int numerator, int denominator) {
    if (denominator == 0) {
        throw std::invalid_argument("Denominator cannot be zero");
    }
    return numerator / denominator;
}

int main() {
    try {
        std::cout << divide(10, 0) << std::endl;
    } catch (const std::invalid_argument& e) {
        std::cerr << "Exception caught: " << e.what() << std::endl;
    }
    return 0;
}
```

### Basic Example 2: Multiple Catch Blocks

```cpp
#include <iostream>
#include <stdexcept>

void riskyFunction() {
    throw std::out_of_range("Out of range error");
}

int main() {
    try {
        riskyFunction();
    } catch (const std::out_of_range& e) {
        std::cerr << "Out of Range Exception: " << e.what() << std::endl;
    } catch (const std::exception& e) {
        std::cerr << "Standard exception: " << e.what() << std::endl;
    }
    return 0;
}
```

## Explanation
When using `try`, there are common pitfalls to be aware of:

- **Uncaught Exceptions**: If an exception is thrown and not caught, the program will terminate. Always ensure that the appropriate `catch` blocks are in place.
- **Resource Management**: If exceptions occur, resources like memory or file handles might not be released properly unless managed carefully. Using RAII (Resource Acquisition Is Initialization) principles can help mitigate this.
- **Catch by Value vs. Reference**: Catching exceptions by value can lead to slicing, where only the base class portion of the exception is caught. Catching by reference preserves the full exception object.
- **Performance Overhead**: Exception handling can introduce performance overhead, so it should be used judiciously, particularly in performance-critical sections of code.

## One Line Summary
The `try` keyword in C++ is essential for defining code blocks where exceptions can occur, facilitating effective error management through structured exception handling.