<!--
Meta Description: # C++ try: Fehlerbehandlung mit Ausnahmen im C++ ## Synopsis Das Schlüsselwort `try` in C++ ist Teil des Mechanismus zur Fehlerbehandlung, der es ermö...
Meta Keywords: try, catch, std, ausnahmen, von
-->

# C++ try: Fehlerbehandlung mit Ausnahmen im C++

## Synopsis
Das Schlüsselwort `try` in C++ ist Teil des Mechanismus zur Fehlerbehandlung, der es ermöglicht, Ausnahmen zu werfen und abzufangen. Es wird verwendet, um code umzuschließen, der potenziell Fehler erzeugen kann, und erlaubt es, auf diese Fehler kontrolliert zu reagieren.

## Documentation
In C++ wird das `try`-Schlüsselwort in Verbindung mit `catch` verwendet, um Ausnahmen zu behandeln. Der Code innerhalb eines `try`-Blocks wird auf Fehler überprüft, und wenn eine Ausnahme auftritt, wird die Kontrolle an den entsprechenden `catch`-Block übergeben.

### Zweck
Der Hauptzweck von `try` ist es, den Programmfluss bei Auftreten eines Fehlers oder einer Ausnahme zu steuern, ohne das gesamte Programm zum Absturz zu bringen.

### Verwendung
Ein `try`-Block wird wie folgt syntaktisch verwendet:

```cpp
try {
    // Code, der eine Ausnahme auslösen könnte
} catch (const std::exception& e) {
    // Fehlerbehandlung
}
```

Innerhalb des `try`-Blocks wird der Code ausgeführt, und wenn eine Ausnahme auftritt, wird der zugehörige `catch`-Block aufgerufen, um die Ausnahme zu verarbeiten.

### Details
- Mehrere `catch`-Blöcke können für unterschiedliche Ausnahmetypen definiert werden.
- Es ist möglich, einen `catch`-Block ohne spezifischen Ausnahmetyp zu verwenden, um alle Ausnahmen abzufangen.
- C++ unterstützt auch die Verwendung von `throw` zum Werfen von Ausnahmen.

## Examples
Hier sind einige grundlegende Beispiele zur Verwendung von `try` in C++:

### Beispiel 1: Einfache Ausnahmebehandlung

```cpp
#include <iostream>
#include <stdexcept>

int main() {
    try {
        throw std::runtime_error("Ein Fehler ist aufgetreten!");
    } catch (const std::runtime_error& e) {
        std::cout << "Fehler gefangen: " << e.what() << std::endl;
    }
    return 0;
}
```

### Beispiel 2: Mehrere `catch`-Blöcke

```cpp
#include <iostream>
#include <stdexcept>

int main() {
    try {
        throw 42; // Werfe eine int-Ausnahme
    } catch (const std::runtime_error& e) {
        std::cout << "Runtime Error: " << e.what() << std::endl;
    } catch (int e) {
        std::cout << "Int Ausnahme gefangen: " << e << std::endl;
    }
    return 0;
}
```

## Explanation
Es gibt einige häufige Probleme und Missverständnisse im Zusammenhang mit `try`:

- **Unbehandelte Ausnahmen**: Wenn eine Ausnahme nicht von einem `catch`-Block behandelt wird, führt dies zu einem Programmabbruch.
- **Ressourcenmanagement**: Es ist wichtig, sicherzustellen, dass alle Ressourcen (wie dynamisch zugewiesener Speicher) auch im Fehlerfall freigegeben werden. Hier können Destruktoren oder RAII (Resource Acquisition Is Initialization) hilfreich sein.
- **Wurf von Ausnahmen**: Nicht alle Typen können geworfen werden. Es ist eine gute Praxis, Ausnahmen von Typen abzuleiten, die von `std::exception` erben.

## One Line Summary
Das `try`-Schlüsselwort in C++ ermöglicht eine strukturierte Fehlerbehandlung durch das Abfangen und Verarbeiten von Ausnahmen.