<!--
Meta Description: # Catch in C++: A Comprehensive Guide to Exception Handling ## Synopsis In C++, the `catch` block is an integral part of the exception handling mechan...
Meta Keywords: catch, exception, std, block, exceptions
-->

# Catch in C++: A Comprehensive Guide to Exception Handling

## Synopsis
In C++, the `catch` block is an integral part of the exception handling mechanism, allowing developers to gracefully handle runtime errors and maintain program stability.

## Documentation
The `catch` statement is used in conjunction with `try` blocks to manage exceptions that may arise during the execution of a program. When an exception is thrown, control is transferred to the nearest `catch` block that matches the type of exception thrown. The primary purpose of `catch` is to provide a way to handle errors without crashing the program, allowing for corrective measures or informative error messages.

### Purpose
- To handle exceptions and errors that occur during runtime.
- To separate normal code flow from error handling code, improving code readability and maintenance.

### Usage
A typical structure for using `catch` in C++ looks like this:

```cpp
try {
    // Code that may throw an exception
} catch (const ExceptionType& e) {
    // Code to handle the exception
}
```

### Details
- Multiple `catch` blocks can follow a single `try` block to handle different exception types.
- A catch block can catch exceptions by value, reference, or pointer.
- The order of `catch` blocks matters; more specific exceptions must be placed before more general exceptions to prevent unreachable code.

## Examples
### Basic Example
Here's a simple example of using `catch` in C++:

```cpp
#include <iostream>
#include <stdexcept>

int main() {
    try {
        throw std::runtime_error("An error occurred!");
    } catch (const std::runtime_error& e) {
        std::cout << "Caught an exception: " << e.what() << std::endl;
    }
    return 0;
}
```

### Multiple Catch Blocks
In this example, we handle different types of exceptions:

```cpp
#include <iostream>
#include <stdexcept>

void testFunction(int value) {
    if (value < 0) {
        throw std::invalid_argument("Negative value is not allowed");
    } else if (value == 0) {
        throw std::runtime_error("Zero value error");
    }
}

int main() {
    try {
        testFunction(-1);
    } catch (const std::invalid_argument& e) {
        std::cout << "Invalid argument: " << e.what() << std::endl;
    } catch (const std::runtime_error& e) {
        std::cout << "Runtime error: " << e.what() << std::endl;
    }
    return 0;
}
```

## Explanation
### Common Pitfalls
- **Unreachable Catch Blocks**: If a more general exception type is placed before a specific one, the specific catch block may never be executed.
- **Exception Type Mismatch**: Ensure that the type of exception thrown matches the type used in the `catch` block.
- **Ignoring Exceptions**: Failing to handle exceptions properly can lead to undefined behavior or application crashes.

### Gotchas
- The `catch` block will only execute if an exception is thrown within its associated `try` block.
- If no matching `catch` block is found, the program will terminate, and a stack unwinding process occurs, which can be resource-intensive.

## One Line Summary
The `catch` statement in C++ provides a mechanism for handling exceptions, enabling developers to create robust and error-resistant applications.