<!--
Meta Description: # C++中的catch语句：异常处理的关键 ## 概述 在C++中，`catch`语句用于处理异常，是异常处理机制的一部分。它与`try`语句配合使用，可以捕获在`try`块中抛出的异常，从而使程序能够处理错误而不崩溃。 ## 文档 ### 目的 `catch`语句的主要目的是捕获和处理在程序执行...
Meta Keywords: catch, std, try, const, throw
-->

# C++中的catch语句：异常处理的关键

## 概述
在C++中，`catch`语句用于处理异常，是异常处理机制的一部分。它与`try`语句配合使用，可以捕获在`try`块中抛出的异常，从而使程序能够处理错误而不崩溃。

## 文档
### 目的
`catch`语句的主要目的是捕获和处理在程序执行期间发生的异常。这有助于提升程序的稳定性和可维护性，确保即使在发生错误时，程序也能优雅地退出或进行其他处理。

### 使用方法
在C++中，`catch`语句通常与`try`块一起使用。`try`块包含可能抛出异常的代码，而`catch`块则定义了如何处理这些异常。

```cpp
try {
    // 可能会抛出异常的代码
} catch (const ExceptionType& e) {
    // 处理异常的代码
}
```

### 详细信息
- **异常类型**：`catch`块可以捕获特定类型的异常，例如标准异常类`std::exception`，也可以自定义异常类。
- **多重捕获**：可以使用多个`catch`块来处理不同类型的异常。
- **捕获所有异常**：可以使用通用的`catch (...)`捕获所有未处理的异常。
- **异常传播**：如果在`catch`块中重新抛出异常，可以使用`throw;`语句将异常传播到调用者。

## 示例
### 基本用法示例
```cpp
#include <iostream>
#include <stdexcept>

void mayThrow() {
    throw std::runtime_error("发生了一个运行时错误");
}

int main() {
    try {
        mayThrow();
    } catch (const std::runtime_error& e) {
        std::cout << "捕获到异常: " << e.what() << std::endl;
    }
    return 0;
}
```

### 捕获多种异常
```cpp
#include <iostream>
#include <stdexcept>

void mayThrow(int flag) {
    if (flag == 1) {
        throw std::runtime_error("运行时错误");
    } else if (flag == 2) {
        throw std::invalid_argument("无效参数错误");
    }
}

int main() {
    try {
        mayThrow(1);
    } catch (const std::runtime_error& e) {
        std::cout << "捕获到运行时异常: " << e.what() << std::endl;
    } catch (const std::invalid_argument& e) {
        std::cout << "捕获到无效参数异常: " << e.what() << std::endl;
    }
    return 0;
}
```

## 解释
- **常见陷阱**：在`catch`块中，如果尝试访问被异常抛出时的局部变量，可能会导致未定义行为，因为这些变量的生命周期已经结束。
- **性能考虑**：过度使用异常处理可能会影响程序性能，特别是在高频率调用的代码中。因此，建议仅在必要时使用异常处理。
- **未处理的异常**：如果异常未在任何`catch`块中被捕获，程序将终止并打印出异常信息。

## 一句话总结
`catch`语句是C++异常处理机制的重要组成部分，用于捕获和处理程序中的错误。