<!--
Meta Description: # C++ 中的 throw 關鍵字：異常處理的核心 ## 概述 在 C++ 中，`throw` 關鍵字用於引發異常，這是進行異常處理的一個重要部分。使用 `throw` 可以在程序運行中遇到錯誤情況時，向調用者報告問題，並允許程序員處理這些錯誤。 ## 文檔 ### 目的 `throw` 使得 C...
Meta Keywords: throw, std, catch, testfunction, value
-->

# C++ 中的 throw 關鍵字：異常處理的核心

## 概述
在 C++ 中，`throw` 關鍵字用於引發異常，這是進行異常處理的一個重要部分。使用 `throw` 可以在程序運行中遇到錯誤情況時，向調用者報告問題，並允許程序員處理這些錯誤。

## 文檔
### 目的
`throw` 使得 C++ 程式可以在發生錯誤或異常狀況時，從當前函數中引發異常，並根據所引發的異常類型進行適當的錯誤處理。

### 使用方法
`throw` 的基本語法為：
```cpp
throw 表達式;
```
其中，`表達式` 可以是任何類型的對象，通常是異常類型的對象。當 `throw` 被執行時，控制權將轉移到最近的異常處理器（即 `catch` 區塊）。

### 詳細說明
- 異常類型：C++ 標準庫中提供了一些內建的異常類型，例如 `std::exception` 和其子類，開發者也可以自定義異常類型。
- 異常的傳遞：當一個 `throw` 被執行時，控制權會從當前執行的程式碼中跳出，然後尋找匹配的 `catch` 區塊。若未找到匹配的 `catch`，則程序將終止。
- 多重異常：C++ 支持多個 `catch` 區塊來處理不同的異常類型。

## 範例
以下是使用 `throw` 的基本範例：

```cpp
#include <iostream>
#include <stdexcept>

void testFunction(int value) {
    if (value < 0) {
        throw std::invalid_argument("負數不被允許");
    }
    std::cout << "值為：" << value << std::endl;
}

int main() {
    try {
        testFunction(-1);
    } catch (const std::invalid_argument& e) {
        std::cerr << "捕獲到異常: " << e.what() << std::endl;
    }
    return 0;
}
```

在上述範例中，當 `testFunction` 接收到負數時，將引發 `std::invalid_argument` 異常，並在 `main` 函數中捕獲。

## 說明
- **常見陷阱**：確保所有可能引發異常的代碼都被適當的 `try-catch` 區塊包圍。否則，未處理的異常會導致程序崩潰。
- **異常安全**：在設計類和函數時，考慮異常安全性是很重要的。使用 RAII（資源獲取即初始化）模式可以幫助確保資源被正確管理。
- **性能考量**：雖然使用 `throw` 會使代碼在錯誤情況下更具可讀性和可維護性，但頻繁使用異常處理可能會影響性能，因此應謹慎使用。

## 一句總結
`throw` 是 C++ 中用於引發異常的關鍵字，使得錯誤處理更為靈活和可靠。