<!--
Meta Description: # C++ 中的 throw 關鍵字：異常處理的核心 ## 摘要 在 C++ 中，`throw` 關鍵字用於引發異常，從而使程式能夠處理錯誤情況並維持其穩定性。使用 `throw` 可以讓開發者清晰地指定何時發生異常，以及如何進行後續處理。 ## 文檔 `throw` 關鍵字的主要目的是在程式運行中...
Meta Keywords: throw, std, include, const, cpp
-->

# C++ 中的 throw 關鍵字：異常處理的核心

## 摘要
在 C++ 中，`throw` 關鍵字用於引發異常，從而使程式能夠處理錯誤情況並維持其穩定性。使用 `throw` 可以讓開發者清晰地指定何時發生異常，以及如何進行後續處理。

## 文檔
`throw` 關鍵字的主要目的是在程式運行中引發異常。當程式遇到錯誤或不符合預期的情況時，可以使用 `throw` 來拋出一個異常對象，這樣就可以跳過當前的代碼執行，並轉移控制到相關的異常處理代碼中。

### 使用方式
`throw` 的基本語法如下：

```cpp
throw expression;
```

這裡的 `expression` 可以是任何類型的對象，通常是自定義的異常類型。

### 詳細說明
當 `throw` 被調用時，程式會立即停止當前函數的執行，並尋找與之匹配的 `catch` 區塊。這種機制使得錯誤處理變得更加結構化和清晰。使用 `throw` 的一個關鍵點是，開發者需要確保異常類型能夠被捕獲，否則將導致程式崩潰。

## 範例
以下是一些 `throw` 的基本使用範例：

### 範例 1：拋出整數異常

```cpp
#include <iostream>
#include <stdexcept>

void checkValue(int value) {
    if (value < 0) {
        throw std::invalid_argument("負數不被接受");
    }
}

int main() {
    try {
        checkValue(-1);
    } catch (const std::invalid_argument& e) {
        std::cout << "捕獲到異常: " << e.what() << std::endl;
    }
    return 0;
}
```

### 範例 2：拋出自定義異常

```cpp
#include <iostream>
#include <string>

class MyException : public std::exception {
public:
    const char* what() const noexcept override {
        return "自定義異常發生！";
    }
};

void riskyFunction() {
    throw MyException();
}

int main() {
    try {
        riskyFunction();
    } catch (const std::exception& e) {
        std::cout << "捕獲到異常: " << e.what() << std::endl;
    }
    return 0;
}
```

## 說明
在使用 `throw` 時，有幾點需要注意：

1. **異常類型**：確保拋出的異常類型可以被捕獲，通常使用 `std::exception` 或其子類型。
2. **資源管理**：在異常發生後，確保釋放已分配的資源，避免內存泄漏。
3. **性能考量**：異常處理會影響性能，應謹慎使用，尤其是在高頻率調用的路徑中。
4. **多重異常**：可以在同一個 `try` 塊中捕獲多種異常，但要注意捕獲順序。

## 一句總結
在 C++ 中，`throw` 關鍵字用於引發異常，從而幫助開發者有效地處理錯誤情況。